<mujoco>

    <include file="basic_scene.xml" />
    <include file="left_leg_stl_assets.xml" />
    <include file="right_leg_stl_assets.xml" />
    <include file="tail_assets/tail_stl_assets.xml" />
    <size njmax="2000" nconmax="2000" />
    <asset>
        <mesh name="head" file="stl-meshes/head_main.stl" scale="0.001 0.001 0.001" />
        <mesh name="head_mounting" file="stl-meshes/head_bracket.stl" scale="0.001 0.001 0.001" />
        <mesh name="main_body" file="stl-meshes/main_chest.stl" scale="0.001 0.001 0.001" />
        <mesh name="spine_t1" file="stl-meshes/spine_t1.stl" scale="0.001 0.001 0.001" />
        <mesh name="spine_t2" file="stl-meshes/spine_t2_zeroed.stl" scale="0.001 0.001 0.001" />
        <mesh name="spine_t3" file="stl-meshes/spine_t3_zeroed.stl" scale="0.001 0.001 0.001" />
        <mesh name="spine_t4" file="stl-meshes/spine_t4_zeroed.stl" scale="0.001 0.001 0.001" />
        <mesh name="hip" file="stl-meshes/hip_zeroed.stl" scale="0.001 0.001 0.001" />
        <mesh name="reel_sm" file="stl-meshes/reel_small.stl" scale="0.001 0.001 0.001" />
        <mesh name="tail" file="stl-meshes/Tail_Unit.stl" scale="0.001 0.001 0.001" />
    </asset>

    <worldbody>
        <light diffuse=".5 .5 .5" pos="0 -1.0 3" dir="0 0 -1" />    
        <geom type="plane" size="0 0 0.03" material="matplane" rgba="1 1 1 1" />
        <camera name="body_cam" mode="fixed" pos="20 0.1 0.05" euler="90 90 0" fovy="1" />
        <camera name="top camera" mode="fixed" pos="0 -1 30" euler="0 0 180" fovy="6" />

        <body name="mouse" pos="0 0 0.1">
            <joint name="rail" type="free" />

            <camera name="tail view camera" mode="track" pos="0 0.35 0.15" euler="110 180 0" fovy="60" />

            <geom name="mouse_body" mass="0.15" type="box" pos="0 0.04 0" size="0.0115 0.048 0.025" rgba="0.8 0.8 0.8 0" />
            <site name="imu" size="0.004" pos="0 0.045 0.01" rgba="0.5 0.5 0.99 1" />
            <body name="visual_mouse_body" pos="0 0 0" euler="0 0 0">
                <geom name="spine_mouse" type="mesh" mesh="main_body" mass="0" contype="0" conaffinity="0" rgba="0.95 0.95 0.95 1" />
            </body>

            <body name="mouse_bracket" pos="0 -0.016 0.013" euler="0 0 0">
                <joint name="neck" pos="0 0 0" type="hinge" axis="0 0 1" damping="0.01" armature="0.00065" limited="true" range="-90 90" ref="0" />
                <geom name="visual_mouse_bracket" type="mesh" mesh="head_mounting" mass="0.005" contype="0" conaffinity="0" rgba="0.95 0.95 0.95 1" />

                <body name="mouse_head" pos="0 -0.0106 0.0144" euler="0 0 0">
                    <joint name="head" pos="0 0 0" type="hinge" axis="1 0 0" damping="0.01" armature="0.00065" limited="true" range="-90 90" ref="0" />
                    <geom name="visual_mouse_head" type="mesh" mesh="head" mass="0.01" contype="0" conaffinity="0" rgba="0.95 0.95 0.95 1" />
                    <camera name="head camera" mode="fixed" pos="0 -0.04 0" euler="90 180 0" />


                    <body name="whisker left hind 1" pos="0.009000000000000001 -0.04 -0.01" euler="0 0 65">

                        <joint name="whisker left hind 11" pos="0 -0.0 -0" type="hinge" axis="-1 -1 0" stiffness="0.02" armature="0.00065" damping="0.02" ref="0" />
                        <joint name="whisker left hind 12" pos="0 -0.0 -0" type="hinge" axis="0 0 1" stiffness="0.02" armature="0.00065" damping="0.02" ref="0" />
                        <geom name="whisk_left hind 1" type="capsule" fromto="0 -0.0 -0 0 -0.005 -0" size="0.001" mass="0.0000001" rgba="0.5 0.5 0.5 1" />
                        <body name="whisker left hind 2" pos="0 0 0" euler="0 0 0">
                            <joint name="whisker left hind 21" pos="0 -0.005 -0" type="hinge" axis="-1 -1 0" stiffness="0.02" armature="0.00065" damping="0.02" ref="0" />
                            <joint name="whisker left hind 22" pos="0 -0.005 -0" type="hinge" axis="0 0 1" stiffness="0.02" armature="0.00065" damping="0.02" ref="0" />
                            <geom name="whisk_left hind 2" type="capsule" fromto="0 -0.005 -0 0 -0.01 -0" size="0.001" mass="0.0000001" rgba="0.5 0.5 0.5 1" />
                            <body name="whisker left hind 3" pos="0 0 0" euler="0 0 0">
                                <joint name="whisker left hind 31" pos="0 -0.01 -0" type="hinge" axis="-1 -1 0" stiffness="0.02" armature="0.00065" damping="0.02" ref="0" />
                                <joint name="whisker left hind 32" pos="0 -0.01 -0" type="hinge" axis="0 0 1" stiffness="0.02" armature="0.00065" damping="0.02" ref="0" />
                                <geom name="whisk_left hind 3" type="capsule" fromto="0 -0.01 -0 0 -0.015 -0" size="0.001" mass="0.0000001" rgba="0.5 0.5 0.5 1" />
                                <body name="whisker left hind 4" pos="0 0 0" euler="0 0 0">
                                    <joint name="whisker left hind 41" pos="0 -0.015 -0" type="hinge" axis="-1 -1 0" stiffness="0.02" armature="0.00065" damping="0.02" ref="0" />
                                    <joint name="whisker left hind 42" pos="0 -0.015 -0" type="hinge" axis="0 0 1" stiffness="0.02" armature="0.00065" damping="0.02" ref="0" />
                                    <geom name="whisk_left hind 4" type="capsule" fromto="0 -0.015 -0 0 -0.02 -0" size="0.001" mass="0.0000001" rgba="0.5 0.5 0.5 1" />
                                    <body name="whisker left hind 5" pos="0 0 0" euler="0 0 0">
                                        <joint name="whisker left hind 51" pos="0 -0.02 -0" type="hinge" axis="-1 -1 0" stiffness="0.02" armature="0.00065" damping="0.02" ref="0" />
                                        <joint name="whisker left hind 52" pos="0 -0.02 -0" type="hinge" axis="0 0 1" stiffness="0.02" armature="0.00065" damping="0.02" ref="0" />
                                        <geom name="whisk_left hind 5" type="capsule" fromto="0 -0.02 -0 0 -0.025 -0" size="0.001" mass="0.0000001" rgba="0.5 0.5 0.5 1" />
                                        <body name="whisker left hind 6" pos="0 0 0" euler="0 0 0">
                                            <joint name="whisker left hind 61" pos="0 -0.025 -0" type="hinge" axis="-1 -1 0" stiffness="0.02" armature="0.00065" damping="0.02" ref="0" />
                                            <joint name="whisker left hind 62" pos="0 -0.025 -0" type="hinge" axis="0 0 1" stiffness="0.02" armature="0.00065" damping="0.02" ref="0" />
                                            <geom name="whisk_left hind 6" type="capsule" fromto="0 -0.025 -0 0 -0.03 -0" size="0.001" mass="0.0000001" rgba="0.5 0.5 0.5 1" />
                                            <body name="whisker left hind 7" pos="0 0 0" euler="0 0 0">
                                                <joint name="whisker left hind 71" pos="0 -0.03 -0" type="hinge" axis="-1 -1 0" stiffness="0.02" armature="0.00065" damping="0.02" ref="0" />
                                                <joint name="whisker left hind 72" pos="0 -0.03 -0" type="hinge" axis="0 0 1" stiffness="0.02" armature="0.00065" damping="0.02" ref="0" />
                                                <geom name="whisk_left hind 7" type="capsule" fromto="0 -0.03 -0 0 -0.035 -0" size="0.001" mass="0.0000001" rgba="0.5 0.5 0.5 1" />
                                                <body name="whisker left hind 8" pos="0 0 0" euler="0 0 0">
                                                    <joint name="whisker left hind 81" pos="0 -0.035 -0" type="hinge" axis="-1 -1 0" stiffness="0.02" armature="0.00065" damping="0.02" ref="0" />
                                                    <joint name="whisker left hind 82" pos="0 -0.035 -0" type="hinge" axis="0 0 1" stiffness="0.02" armature="0.00065" damping="0.02" ref="0" />
                                                    <geom name="whisk_left hind 8" type="capsule" fromto="0 -0.035 -0 0 -0.04 -0" size="0.001" mass="0.0000001" rgba="0.5 0.5 0.5 1" />
                                                    <body name="whisker left hind 9" pos="0 0 0" euler="0 0 0">
                                                        <joint name="whisker left hind 91" pos="0 -0.04 -0" type="hinge" axis="-1 -1 0" stiffness="0.02" armature="0.00065" damping="0.02" ref="0" />
                                                        <joint name="whisker left hind 92" pos="0 -0.04 -0" type="hinge" axis="0 0 1" stiffness="0.02" armature="0.00065" damping="0.02" ref="0" />
                                                        <geom name="whisk_left hind 9" type="capsule" fromto="0 -0.04 -0 0 -0.045 -0" size="0.001" mass="0.0000001" rgba="0.5 0.5 0.5 1" />
                                                        <body name="whisker left hind 10" pos="0 0 0" euler="0 0 0">
                                                            <joint name="whisker left hind 101" pos="0 -0.045 -0" type="hinge" axis="-1 -1 0" stiffness="0.02" armature="0.00065" damping="0.02" ref="0" />
                                                            <joint name="whisker left hind 102" pos="0 -0.045 -0" type="hinge" axis="0 0 1" stiffness="0.02" armature="0.00065" damping="0.02" ref="0" />
                                                            <geom name="whisk_left hind 10" type="capsule" fromto="0 -0.045 -0 0 -0.05 -0" size="0.001" mass="0.0000001" rgba="0.5 0.5 0.5 1" />
                                                            <body name="whisker left hind 11" pos="0 0 0" euler="0 0 0">
                                                                <joint name="whisker left hind 111" pos="0 -0.05 -0" type="hinge" axis="-1 -1 0" stiffness="0.02" armature="0.00065" damping="0.02" ref="0" />
                                                                <joint name="whisker left hind 112" pos="0 -0.05 -0" type="hinge" axis="0 0 1" stiffness="0.02" armature="0.00065" damping="0.02" ref="0" />
                                                                <geom name="whisk_left hind 11" type="capsule" fromto="0 -0.05 -0 0 -0.055 -0" size="0.001" mass="0.0000001" rgba="0.5 0.5 0.5 1" />
                                                                <body name="whisker left hind 12" pos="0 0 0" euler="0 0 0">
                                                                    <joint name="whisker left hind 121" pos="0 -0.055 -0" type="hinge" axis="-1 -1 0" stiffness="0.02" armature="0.00065" damping="0.02" ref="0" />
                                                                    <joint name="whisker left hind 122" pos="0 -0.055 -0" type="hinge" axis="0 0 1" stiffness="0.02" armature="0.00065" damping="0.02" ref="0" />
                                                                    <geom name="whisk_left hind 12" type="capsule" fromto="0 -0.055 -0 0 -0.06 -0" size="0.001" mass="0.0000001" rgba="0.5 0.5 0.5 1" />

                                                                </body>
                                                            </body>
                                                        </body>
                                                    </body>
                                                </body>
                                            </body>
                                        </body>
                                    </body>
                                </body>
                            </body>
                        </body>
                    </body>
                    <body name="whisker left front 1" pos="0.002 -0.05 -0.01" euler="0 0 45">

                        <joint name="whisker left front 11" pos="0 -0.0 -0" type="hinge" axis="-1 -1 0" stiffness="0.02" armature="0.00065" damping="0.02" ref="0" />
                        <joint name="whisker left front 12" pos="0 -0.0 -0" type="hinge" axis="0 0 1" stiffness="0.02" armature="0.00065" damping="0.02" ref="0" />
                        <geom name="whisk_left front 1" type="capsule" fromto="0 -0.0 -0 0 -0.005 -0" size="0.001" mass="0.0000001" rgba="0.5 0.5 0.5 1" />
                        <body name="whisker left front 2" pos="0 0 0" euler="0 0 0">
                            <joint name="whisker left front 21" pos="0 -0.005 -0" type="hinge" axis="-1 -1 0" stiffness="0.02" armature="0.00065" damping="0.02" ref="0" />
                            <joint name="whisker left front 22" pos="0 -0.005 -0" type="hinge" axis="0 0 1" stiffness="0.02" armature="0.00065" damping="0.02" ref="0" />
                            <geom name="whisk_left front 2" type="capsule" fromto="0 -0.005 -0 0 -0.01 -0" size="0.001" mass="0.0000001" rgba="0.5 0.5 0.5 1" />
                            <body name="whisker left front 3" pos="0 0 0" euler="0 0 0">
                                <joint name="whisker left front 31" pos="0 -0.01 -0" type="hinge" axis="-1 -1 0" stiffness="0.02" armature="0.00065" damping="0.02" ref="0" />
                                <joint name="whisker left front 32" pos="0 -0.01 -0" type="hinge" axis="0 0 1" stiffness="0.02" armature="0.00065" damping="0.02" ref="0" />
                                <geom name="whisk_left front 3" type="capsule" fromto="0 -0.01 -0 0 -0.015 -0" size="0.001" mass="0.0000001" rgba="0.5 0.5 0.5 1" />
                                <body name="whisker left front 4" pos="0 0 0" euler="0 0 0">
                                    <joint name="whisker left front 41" pos="0 -0.015 -0" type="hinge" axis="-1 -1 0" stiffness="0.02" armature="0.00065" damping="0.02" ref="0" />
                                    <joint name="whisker left front 42" pos="0 -0.015 -0" type="hinge" axis="0 0 1" stiffness="0.02" armature="0.00065" damping="0.02" ref="0" />
                                    <geom name="whisk_left front 4" type="capsule" fromto="0 -0.015 -0 0 -0.02 -0" size="0.001" mass="0.0000001" rgba="0.5 0.5 0.5 1" />
                                    <body name="whisker left front 5" pos="0 0 0" euler="0 0 0">
                                        <joint name="whisker left front 51" pos="0 -0.02 -0" type="hinge" axis="-1 -1 0" stiffness="0.02" armature="0.00065" damping="0.02" ref="0" />
                                        <joint name="whisker left front 52" pos="0 -0.02 -0" type="hinge" axis="0 0 1" stiffness="0.02" armature="0.00065" damping="0.02" ref="0" />
                                        <geom name="whisk_left front 5" type="capsule" fromto="0 -0.02 -0 0 -0.025 -0" size="0.001" mass="0.0000001" rgba="0.5 0.5 0.5 1" />
                                        <body name="whisker left front 6" pos="0 0 0" euler="0 0 0">
                                            <joint name="whisker left front 61" pos="0 -0.025 -0" type="hinge" axis="-1 -1 0" stiffness="0.02" armature="0.00065" damping="0.02" ref="0" />
                                            <joint name="whisker left front 62" pos="0 -0.025 -0" type="hinge" axis="0 0 1" stiffness="0.02" armature="0.00065" damping="0.02" ref="0" />
                                            <geom name="whisk_left front 6" type="capsule" fromto="0 -0.025 -0 0 -0.03 -0" size="0.001" mass="0.0000001" rgba="0.5 0.5 0.5 1" />
                                            <body name="whisker left front 7" pos="0 0 0" euler="0 0 0">
                                                <joint name="whisker left front 71" pos="0 -0.03 -0" type="hinge" axis="-1 -1 0" stiffness="0.02" armature="0.00065" damping="0.02" ref="0" />
                                                <joint name="whisker left front 72" pos="0 -0.03 -0" type="hinge" axis="0 0 1" stiffness="0.02" armature="0.00065" damping="0.02" ref="0" />
                                                <geom name="whisk_left front 7" type="capsule" fromto="0 -0.03 -0 0 -0.035 -0" size="0.001" mass="0.0000001" rgba="0.5 0.5 0.5 1" />
                                                <body name="whisker left front 8" pos="0 0 0" euler="0 0 0">
                                                    <joint name="whisker left front 81" pos="0 -0.035 -0" type="hinge" axis="-1 -1 0" stiffness="0.02" armature="0.00065" damping="0.02" ref="0" />
                                                    <joint name="whisker left front 82" pos="0 -0.035 -0" type="hinge" axis="0 0 1" stiffness="0.02" armature="0.00065" damping="0.02" ref="0" />
                                                    <geom name="whisk_left front 8" type="capsule" fromto="0 -0.035 -0 0 -0.04 -0" size="0.001" mass="0.0000001" rgba="0.5 0.5 0.5 1" />
                                                    <body name="whisker left front 9" pos="0 0 0" euler="0 0 0">
                                                        <joint name="whisker left front 91" pos="0 -0.04 -0" type="hinge" axis="-1 -1 0" stiffness="0.02" armature="0.00065" damping="0.02" ref="0" />
                                                        <joint name="whisker left front 92" pos="0 -0.04 -0" type="hinge" axis="0 0 1" stiffness="0.02" armature="0.00065" damping="0.02" ref="0" />
                                                        <geom name="whisk_left front 9" type="capsule" fromto="0 -0.04 -0 0 -0.045 -0" size="0.001" mass="0.0000001" rgba="0.5 0.5 0.5 1" />
                                                        <body name="whisker left front 10" pos="0 0 0" euler="0 0 0">
                                                            <joint name="whisker left front 101" pos="0 -0.045 -0" type="hinge" axis="-1 -1 0" stiffness="0.02" armature="0.00065" damping="0.02" ref="0" />
                                                            <joint name="whisker left front 102" pos="0 -0.045 -0" type="hinge" axis="0 0 1" stiffness="0.02" armature="0.00065" damping="0.02" ref="0" />
                                                            <geom name="whisk_left front 10" type="capsule" fromto="0 -0.045 -0 0 -0.05 -0" size="0.001" mass="0.0000001" rgba="0.5 0.5 0.5 1" />

                                                        </body>
                                                    </body>
                                                </body>
                                            </body>
                                        </body>
                                    </body>
                                </body>
                            </body>
                        </body>
                    </body>
                    <body name="whisker right hind 1" pos="-0.007 -0.04 -0.01" euler="0 0 -65">

                        <joint name="whisker right hind 11" pos="0 -0.0 -0" type="hinge" axis="-1 -1 0" stiffness="0.02" armature="0.00065" damping="0.02" ref="0" />
                        <joint name="whisker right hind 12" pos="0 -0.0 -0" type="hinge" axis="0 0 1" stiffness="0.02" armature="0.00065" damping="0.02" ref="0" />
                        <geom name="whisk_right hind 1" type="capsule" fromto="0 -0.0 -0 0 -0.005 -0" size="0.001" mass="0.0000001" rgba="0.5 0.5 0.5 1" />
                        <body name="whisker right hind 2" pos="0 0 0" euler="0 0 0">
                            <joint name="whisker right hind 21" pos="0 -0.005 -0" type="hinge" axis="-1 -1 0" stiffness="0.02" armature="0.00065" damping="0.02" ref="0" />
                            <joint name="whisker right hind 22" pos="0 -0.005 -0" type="hinge" axis="0 0 1" stiffness="0.02" armature="0.00065" damping="0.02" ref="0" />
                            <geom name="whisk_right hind 2" type="capsule" fromto="0 -0.005 -0 0 -0.01 -0" size="0.001" mass="0.0000001" rgba="0.5 0.5 0.5 1" />
                            <body name="whisker right hind 3" pos="0 0 0" euler="0 0 0">
                                <joint name="whisker right hind 31" pos="0 -0.01 -0" type="hinge" axis="-1 -1 0" stiffness="0.02" armature="0.00065" damping="0.02" ref="0" />
                                <joint name="whisker right hind 32" pos="0 -0.01 -0" type="hinge" axis="0 0 1" stiffness="0.02" armature="0.00065" damping="0.02" ref="0" />
                                <geom name="whisk_right hind 3" type="capsule" fromto="0 -0.01 -0 0 -0.015 -0" size="0.001" mass="0.0000001" rgba="0.5 0.5 0.5 1" />
                                <body name="whisker right hind 4" pos="0 0 0" euler="0 0 0">
                                    <joint name="whisker right hind 41" pos="0 -0.015 -0" type="hinge" axis="-1 -1 0" stiffness="0.02" armature="0.00065" damping="0.02" ref="0" />
                                    <joint name="whisker right hind 42" pos="0 -0.015 -0" type="hinge" axis="0 0 1" stiffness="0.02" armature="0.00065" damping="0.02" ref="0" />
                                    <geom name="whisk_right hind 4" type="capsule" fromto="0 -0.015 -0 0 -0.02 -0" size="0.001" mass="0.0000001" rgba="0.5 0.5 0.5 1" />
                                    <body name="whisker right hind 5" pos="0 0 0" euler="0 0 0">
                                        <joint name="whisker right hind 51" pos="0 -0.02 -0" type="hinge" axis="-1 -1 0" stiffness="0.02" armature="0.00065" damping="0.02" ref="0" />
                                        <joint name="whisker right hind 52" pos="0 -0.02 -0" type="hinge" axis="0 0 1" stiffness="0.02" armature="0.00065" damping="0.02" ref="0" />
                                        <geom name="whisk_right hind 5" type="capsule" fromto="0 -0.02 -0 0 -0.025 -0" size="0.001" mass="0.0000001" rgba="0.5 0.5 0.5 1" />
                                        <body name="whisker right hind 6" pos="0 0 0" euler="0 0 0">
                                            <joint name="whisker right hind 61" pos="0 -0.025 -0" type="hinge" axis="-1 -1 0" stiffness="0.02" armature="0.00065" damping="0.02" ref="0" />
                                            <joint name="whisker right hind 62" pos="0 -0.025 -0" type="hinge" axis="0 0 1" stiffness="0.02" armature="0.00065" damping="0.02" ref="0" />
                                            <geom name="whisk_right hind 6" type="capsule" fromto="0 -0.025 -0 0 -0.03 -0" size="0.001" mass="0.0000001" rgba="0.5 0.5 0.5 1" />
                                            <body name="whisker right hind 7" pos="0 0 0" euler="0 0 0">
                                                <joint name="whisker right hind 71" pos="0 -0.03 -0" type="hinge" axis="-1 -1 0" stiffness="0.02" armature="0.00065" damping="0.02" ref="0" />
                                                <joint name="whisker right hind 72" pos="0 -0.03 -0" type="hinge" axis="0 0 1" stiffness="0.02" armature="0.00065" damping="0.02" ref="0" />
                                                <geom name="whisk_right hind 7" type="capsule" fromto="0 -0.03 -0 0 -0.035 -0" size="0.001" mass="0.0000001" rgba="0.5 0.5 0.5 1" />
                                                <body name="whisker right hind 8" pos="0 0 0" euler="0 0 0">
                                                    <joint name="whisker right hind 81" pos="0 -0.035 -0" type="hinge" axis="-1 -1 0" stiffness="0.02" armature="0.00065" damping="0.02" ref="0" />
                                                    <joint name="whisker right hind 82" pos="0 -0.035 -0" type="hinge" axis="0 0 1" stiffness="0.02" armature="0.00065" damping="0.02" ref="0" />
                                                    <geom name="whisk_right hind 8" type="capsule" fromto="0 -0.035 -0 0 -0.04 -0" size="0.001" mass="0.0000001" rgba="0.5 0.5 0.5 1" />
                                                    <body name="whisker right hind 9" pos="0 0 0" euler="0 0 0">
                                                        <joint name="whisker right hind 91" pos="0 -0.04 -0" type="hinge" axis="-1 -1 0" stiffness="0.02" armature="0.00065" damping="0.02" ref="0" />
                                                        <joint name="whisker right hind 92" pos="0 -0.04 -0" type="hinge" axis="0 0 1" stiffness="0.02" armature="0.00065" damping="0.02" ref="0" />
                                                        <geom name="whisk_right hind 9" type="capsule" fromto="0 -0.04 -0 0 -0.045 -0" size="0.001" mass="0.0000001" rgba="0.5 0.5 0.5 1" />
                                                        <body name="whisker right hind 10" pos="0 0 0" euler="0 0 0">
                                                            <joint name="whisker right hind 101" pos="0 -0.045 -0" type="hinge" axis="-1 -1 0" stiffness="0.02" armature="0.00065" damping="0.02" ref="0" />
                                                            <joint name="whisker right hind 102" pos="0 -0.045 -0" type="hinge" axis="0 0 1" stiffness="0.02" armature="0.00065" damping="0.02" ref="0" />
                                                            <geom name="whisk_right hind 10" type="capsule" fromto="0 -0.045 -0 0 -0.05 -0" size="0.001" mass="0.0000001" rgba="0.5 0.5 0.5 1" />
                                                            <body name="whisker right hind 11" pos="0 0 0" euler="0 0 0">
                                                                <joint name="whisker right hind 111" pos="0 -0.05 -0" type="hinge" axis="-1 -1 0" stiffness="0.02" armature="0.00065" damping="0.02" ref="0" />
                                                                <joint name="whisker right hind 112" pos="0 -0.05 -0" type="hinge" axis="0 0 1" stiffness="0.02" armature="0.00065" damping="0.02" ref="0" />
                                                                <geom name="whisk_right hind 11" type="capsule" fromto="0 -0.05 -0 0 -0.055 -0" size="0.001" mass="0.0000001" rgba="0.5 0.5 0.5 1" />
                                                                <body name="whisker right hind 12" pos="0 0 0" euler="0 0 0">
                                                                    <joint name="whisker right hind 121" pos="0 -0.055 -0" type="hinge" axis="-1 -1 0" stiffness="0.02" armature="0.00065" damping="0.02" ref="0" />
                                                                    <joint name="whisker right hind 122" pos="0 -0.055 -0" type="hinge" axis="0 0 1" stiffness="0.02" armature="0.00065" damping="0.02" ref="0" />
                                                                    <geom name="whisk_right hind 12" type="capsule" fromto="0 -0.055 -0 0 -0.06 -0" size="0.001" mass="0.0000001" rgba="0.5 0.5 0.5 1" />

                                                                </body>
                                                            </body>
                                                        </body>
                                                    </body>
                                                </body>
                                            </body>
                                        </body>
                                    </body>
                                </body>
                            </body>
                        </body>
                    </body>
                    <body name="whisker right front 1" pos="0.0 -0.05 -0.01" euler="0 0 -45">

                        <joint name="whisker right front 11" pos="0 -0.0 -0" type="hinge" axis="-1 -1 0" stiffness="0.02" armature="0.00065" damping="0.02" ref="0" />
                        <joint name="whisker right front 12" pos="0 -0.0 -0" type="hinge" axis="0 0 1" stiffness="0.02" armature="0.00065" damping="0.02" ref="0" />
                        <geom name="whisk_right front 1" type="capsule" fromto="0 -0.0 -0 0 -0.005 -0" size="0.001" mass="0.0000001" rgba="0.5 0.5 0.5 1" />
                        <body name="whisker right front 2" pos="0 0 0" euler="0 0 0">
                            <joint name="whisker right front 21" pos="0 -0.005 -0" type="hinge" axis="-1 -1 0" stiffness="0.02" armature="0.00065" damping="0.02" ref="0" />
                            <joint name="whisker right front 22" pos="0 -0.005 -0" type="hinge" axis="0 0 1" stiffness="0.02" armature="0.00065" damping="0.02" ref="0" />
                            <geom name="whisk_right front 2" type="capsule" fromto="0 -0.005 -0 0 -0.01 -0" size="0.001" mass="0.0000001" rgba="0.5 0.5 0.5 1" />
                            <body name="whisker right front 3" pos="0 0 0" euler="0 0 0">
                                <joint name="whisker right front 31" pos="0 -0.01 -0" type="hinge" axis="-1 -1 0" stiffness="0.02" armature="0.00065" damping="0.02" ref="0" />
                                <joint name="whisker right front 32" pos="0 -0.01 -0" type="hinge" axis="0 0 1" stiffness="0.02" armature="0.00065" damping="0.02" ref="0" />
                                <geom name="whisk_right front 3" type="capsule" fromto="0 -0.01 -0 0 -0.015 -0" size="0.001" mass="0.0000001" rgba="0.5 0.5 0.5 1" />
                                <body name="whisker right front 4" pos="0 0 0" euler="0 0 0">
                                    <joint name="whisker right front 41" pos="0 -0.015 -0" type="hinge" axis="-1 -1 0" stiffness="0.02" armature="0.00065" damping="0.02" ref="0" />
                                    <joint name="whisker right front 42" pos="0 -0.015 -0" type="hinge" axis="0 0 1" stiffness="0.02" armature="0.00065" damping="0.02" ref="0" />
                                    <geom name="whisk_right front 4" type="capsule" fromto="0 -0.015 -0 0 -0.02 -0" size="0.001" mass="0.0000001" rgba="0.5 0.5 0.5 1" />
                                    <body name="whisker right front 5" pos="0 0 0" euler="0 0 0">
                                        <joint name="whisker right front 51" pos="0 -0.02 -0" type="hinge" axis="-1 -1 0" stiffness="0.02" armature="0.00065" damping="0.02" ref="0" />
                                        <joint name="whisker right front 52" pos="0 -0.02 -0" type="hinge" axis="0 0 1" stiffness="0.02" armature="0.00065" damping="0.02" ref="0" />
                                        <geom name="whisk_right front 5" type="capsule" fromto="0 -0.02 -0 0 -0.025 -0" size="0.001" mass="0.0000001" rgba="0.5 0.5 0.5 1" />
                                        <body name="whisker right front 6" pos="0 0 0" euler="0 0 0">
                                            <joint name="whisker right front 61" pos="0 -0.025 -0" type="hinge" axis="-1 -1 0" stiffness="0.02" armature="0.00065" damping="0.02" ref="0" />
                                            <joint name="whisker right front 62" pos="0 -0.025 -0" type="hinge" axis="0 0 1" stiffness="0.02" armature="0.00065" damping="0.02" ref="0" />
                                            <geom name="whisk_right front 6" type="capsule" fromto="0 -0.025 -0 0 -0.03 -0" size="0.001" mass="0.0000001" rgba="0.5 0.5 0.5 1" />
                                            <body name="whisker right front 7" pos="0 0 0" euler="0 0 0">
                                                <joint name="whisker right front 71" pos="0 -0.03 -0" type="hinge" axis="-1 -1 0" stiffness="0.02" armature="0.00065" damping="0.02" ref="0" />
                                                <joint name="whisker right front 72" pos="0 -0.03 -0" type="hinge" axis="0 0 1" stiffness="0.02" armature="0.00065" damping="0.02" ref="0" />
                                                <geom name="whisk_right front 7" type="capsule" fromto="0 -0.03 -0 0 -0.035 -0" size="0.001" mass="0.0000001" rgba="0.5 0.5 0.5 1" />
                                                <body name="whisker right front 8" pos="0 0 0" euler="0 0 0">
                                                    <joint name="whisker right front 81" pos="0 -0.035 -0" type="hinge" axis="-1 -1 0" stiffness="0.02" armature="0.00065" damping="0.02" ref="0" />
                                                    <joint name="whisker right front 82" pos="0 -0.035 -0" type="hinge" axis="0 0 1" stiffness="0.02" armature="0.00065" damping="0.02" ref="0" />
                                                    <geom name="whisk_right front 8" type="capsule" fromto="0 -0.035 -0 0 -0.04 -0" size="0.001" mass="0.0000001" rgba="0.5 0.5 0.5 1" />
                                                    <body name="whisker right front 9" pos="0 0 0" euler="0 0 0">
                                                        <joint name="whisker right front 91" pos="0 -0.04 -0" type="hinge" axis="-1 -1 0" stiffness="0.02" armature="0.00065" damping="0.02" ref="0" />
                                                        <joint name="whisker right front 92" pos="0 -0.04 -0" type="hinge" axis="0 0 1" stiffness="0.02" armature="0.00065" damping="0.02" ref="0" />
                                                        <geom name="whisk_right front 9" type="capsule" fromto="0 -0.04 -0 0 -0.045 -0" size="0.001" mass="0.0000001" rgba="0.5 0.5 0.5 1" />
                                                        <body name="whisker right front 10" pos="0 0 0" euler="0 0 0">
                                                            <joint name="whisker right front 101" pos="0 -0.045 -0" type="hinge" axis="-1 -1 0" stiffness="0.02" armature="0.00065" damping="0.02" ref="0" />
                                                            <joint name="whisker right front 102" pos="0 -0.045 -0" type="hinge" axis="0 0 1" stiffness="0.02" armature="0.00065" damping="0.02" ref="0" />
                                                            <geom name="whisk_right front 10" type="capsule" fromto="0 -0.045 -0 0 -0.05 -0" size="0.001" mass="0.0000001" rgba="0.5 0.5 0.5 1" />

                                                        </body>
                                                    </body>
                                                </body>
                                            </body>
                                        </body>
                                    </body>
                                </body>
                            </body>
                        </body>
                    </body>






                </body>
            </body>

            
            <body name="fl" pos="0.0115 0 0">
                <include file="leg_fl_assets/fl_asset_exp.xml" />
            </body>

            
            <body name="fr" pos="-0.0115 0 0">
                <include file="leg_fr_assets/fr_asset_exp.xml" />
            </body>

            
            
            <body pos="0 0.064 0.026" name="t1">
                <geom name="visual_t1" type="mesh" mesh="spine_t1" mass="0.002" contype="0" conaffinity="0" rgba="0.95 0.95 0.95 1" />
                
                <site name="body_ss" pos="0 0 0" size="0.002" rgba=".9 .9 0 1" />

                <site name="s2_ss" pos="0.0065 0 0" size="0.002" rgba="1 .4 .4 0.3" />
                <site name="s3_ss" pos="-0.0065 0 0" size="0.002" rgba="1 .4 .4 0.3" />

                <site name="s4_ss" pos="0.0065 0.005 -0.0008" size="0.002" rgba="1 .4 .4 0.3" />
                <site name="s5_ss" pos="-0.0065 0.005 -0.0008" size="0.002" rgba="1 .4 .4 0.3" />
                <body pos="0 0.0084 -0.001" name="t2" euler="-11.4 0 0">
                    <joint name="t2" pos="0 0 0" type="hinge" axis="0 0 1" damping="0.01" stiffness="1.2" armature="0.00065" limited="true" range="-90 90" ref="0" />
                    <geom name="visual_t2" type="mesh" mesh="spine_t2" mass="0.002" contype="0" conaffinity="0" rgba="0.95 0.95 0.95 1" />

                    <site name="s6_ss" pos="0.0065 0.0035 -0.0006" size="0.002" rgba="1 .4 .4 0.3" />
                    <site name="s7_ss" pos="-0.0065 0.0035 -0.0006" size="0.002" rgba="1 .4 .4 0.3" />

                    <site name="s8_ss" pos="0.0065 0.011 -0.0012" size="0.002" rgba="1 .4 .4 0.3" />
                    <site name="s9_ss" pos="-0.0065 0.011 -0.0012" size="0.002" rgba="1 .4 .4 0.3" />
                    <body pos="0 0.014 -0.00075" name="t3" euler="-6.9 0 0">
                        <joint name="t3" pos="0 0 0" type="hinge" axis="0 0 1" damping="0.01" stiffness="1.2" armature="0.00065" limited="true" range="-90 90" ref="0" />
                        <geom name="visual_t3" type="mesh" mesh="spine_t3" mass="0.002" contype="0" conaffinity="0" rgba="0.95 0.95 0.95 1" />
        
                        <site name="s10_ss" pos="0.0065 0.0035 -0.0006" size="0.002" rgba="1 .4 .4 0.3" />
                        <site name="s11_ss" pos="-0.0065 0.0035 -0.0006" size="0.002" rgba="1 .4 .4 0.3" />

                        <site name="s12_ss" pos="0.0065 0.011 -0.0012" size="0.002" rgba="1 .4 .4 0.3" />
                        <site name="s13_ss" pos="-0.0065 0.011 -0.0012" size="0.002" rgba="1 .4 .4 0.3" />

                        <body pos="0 0.014 -0.00075" name="t4" euler="-5.4 0 0">
                            <joint name="t4" pos="0 0 0" type="hinge" axis="0 0 1" damping="0.01" stiffness="1.2" armature="0.00065" limited="true" range="-90 90" ref="0" />
                            <geom name="visual_t4" type="mesh" mesh="spine_t4" mass="0.002" contype="0" conaffinity="0" rgba="0.95 0.95 0.95 1" />

                            <site name="s14_ss" pos="0.0065 0.0035 -0.0006" size="0.002" rgba="1 .4 .4 0.3" />
                            <site name="s15_ss" pos="-0.0065 0.0035 -0.0006" size="0.002" rgba="1 .4 .4 0.3" />

                            <site name="s16_ss" pos="0.0065 0.014 -0.0014" size="0.002" rgba="1 .4 .4 0.3" />
                            <site name="s17_ss" pos="-0.0065 0.014 -0.0014" size="0.002" rgba="1 .4 .4 0.3" />

                            <body pos="0 0.0165 -0.0009" name="hip" euler="8.8 0 0">
                                <joint name="hip" pos="0 0 0" type="hinge" axis="0 0 1" damping="0.01" stiffness="1.2" armature="0.00065" limited="true" range="-90 90" ref="0" />
                                <geom name="visual_hip" type="mesh" mesh="hip" mass="0.06" contype="0" conaffinity="0" rgba="0.95 0.95 0.95 0.4" />

                                <site name="s18_ss" pos="0.0065 0.002 -0.0005" size="0.002" rgba="1 .4 .4 0.3" />
                                <site name="s19_ss" pos="-0.0065 0.002 -0.0005" size="0.002" rgba="1 .4 .4 0.3" />

                                <site name="sx1_ss" pos="0.01 0.0107 -0.0005" size="0.002" rgba="1 .4 .4 0.3" />
                                <site name="sx2_ss" pos="-0.01 0.0107 -0.0005" size="0.002" rgba="1 .4 .4 0.3" />

                                <body name="servo_spine" pos="0 0.0107 0" euler="3 0 0">
                                    <geom name="m_ss" type="cylinder" mass="0.002" fromto="0 0 -0.00165 0 0 0.00165" size="0.0065" rgba=".8 .1 .1 1" conaffinity="0" />
                                    <joint name="m_ss" pos="0 0 0" type="hinge" axis="0 0 1" armature="0.00065" damping="0.01" limited="true" range="-180 180" />

                                    <body name="visual_m_ss" pos="0 0 -0.0015" euler="90 0 0">
                                        <geom name="visual_m_ss" type="mesh" mesh="reel_sm" mass="0" contype="0" conaffinity="0" rgba=".8 .1 .1 1" />
                                    </body>

                                    <site name="s1_ss" pos="0 0.007 0" size="0.002" rgba="1 .4 .4 0.3" />
                                </body>

                                <body name="rl" pos="0.0175 0.0085 0" euler="11.9 0 0">
                                    <include file="leg_rl_assets/rl_asset_exp.xml" />
                                </body>
                                
                                <body name="rr" pos="-0.0175 0.0085 0" euler="11.9 0 0">
                                    <include file="leg_rr_assets/rr_asset_exp.xml" />
                                </body>
                                

                                <body name="visual_mouse_tail" pos="0 0.0217 0.0028" euler="15 0 0">
                                    <include file="tail_assets/tail.xml" />
                                </body>
                            </body>
                        </body>
                    </body>
                </body>
            </body>
        </body>

        
        <include file="test_environment/maze0.xml" />

    </worldbody>
    <equality>
        <connect anchor="0 0 0" body1="thigh_up_link_1_fl" body2="thigh_up_link_2_fl" solimp="1 1 0.001" />
        <connect anchor="0 0 0" body1="thigh_up_link_1_fr" body2="thigh_up_link_2_fr" solimp="1 1 0.001" />
        <connect anchor="0 0 0" body1="thigh_up_link_1_rl" body2="thigh_up_link_2_rl" solimp="1 1 0.001" />
        <connect anchor="0 0 0" body1="thigh_up_link_1_rr" body2="thigh_up_link_2_rr" solimp="1 1 0.001" />
        
    </equality>
    <contact>
        <exclude body1="main_leg_fl" body2="servo_horn_fl" />
        <exclude body1="main_leg_fr" body2="servo_horn_fr" />
        <exclude body1="main_leg_rl" body2="servo_horn_rl" />
        <exclude body1="main_leg_rr" body2="servo_horn_rr" />
    </contact>
    
    <include file="leg_fl_assets/fl_tendon.xml" />
    <include file="leg_fr_assets/fr_tendon.xml" />
    <include file="leg_rl_assets/rl_tendon.xml" />
    <include file="leg_rr_assets/rr_tendon.xml" />
    <include file="tail_assets/tail_tendon.xml" />


    
    


    <tendon>
        <spatial name="m1_tendon_ss" limited="true" range="0 0.07405" width="0.0005" rgba="1 .4 .4 0.3">
            <site site="s1_ss" />
            <geom geom="m_ss" sidesite="sx1_ss" />
            <site site="s18_ss" />
            <site site="s16_ss" />
            <site site="s14_ss" />
            <site site="s12_ss" />
            <site site="s10_ss" />
            <site site="s8_ss" />
            <site site="s6_ss" />
            <site site="s4_ss" />
            <site site="s2_ss" />
        </spatial>

        <spatial name="m2_tendon_ss" limited="true" range="0 0.07405" width="0.0005" rgba="1 .4 .4 0.3">
            <site site="s1_ss" />
            <geom geom="m_ss" sidesite="sx2_ss" />
            <site site="s19_ss" />
            <site site="s17_ss" />
            <site site="s15_ss" />
            <site site="s13_ss" />
            <site site="s11_ss" />
            <site site="s9_ss" />
            <site site="s7_ss" />
            <site site="s5_ss" />
            <site site="s3_ss" />
        </spatial>
    </tendon>

    
    
    <include file="leg_fl_assets/fl_sensor_actuator.xml" />
    <include file="leg_fr_assets/fr_sensor_actuator.xml" />
    <include file="leg_rl_assets/rl_sensor_actuator.xml" />
    <include file="leg_rr_assets/rr_sensor_actuator.xml" />
    <include file="tail_assets/tail_sensor_actuator.xml" />

    <sensor>
        <jointpos name="neck" joint="neck" />
        <jointpos name="head" joint="head" />
        <jointpos name="spine" joint="m_ss" />
        <framepos name="com_pos" objtype="site" objname="imu" />
        <framequat name="com_quat" objtype="site" objname="imu" />
        <framelinvel name="com_vel" objtype="site" objname="imu" />
        <accelerometer name="imu_acc" site="imu" />
        <gyro name="imu_gyro" site="imu" />
    </sensor>

    <actuator>
        <position name="neck" gear="1" ctrllimited="true" ctrlrange="-1.57 1.57" forcelimited="true" forcerange="-.157 .157" joint="neck" kp="100" />
        <position name="head" gear="1" ctrllimited="true" ctrlrange="-1.57 1.57" forcelimited="true" forcerange="-.157 .157" joint="head" kp="100" />
        <position name="spine" gear="1" ctrllimited="true" ctrlrange="-1.57 1.57" forcelimited="true" forcerange="-.157 .157" joint="m_ss" kp="300" />
    </actuator>
</mujoco>