<mujoco>

    <include file="basic_scene.xml" />
    <asset>
        <mesh name="head" file="stl-meshes/head_main.stl" scale="0.001 0.001 0.001" />
        <mesh name="head_mounting" file="stl-meshes/head_bracket.stl" scale="0.001 0.001 0.001" />
    </asset>


    <worldbody>
        <light diffuse=".5 .5 .5" pos="0 -1.0 3" dir="0 0 -1" />
        <geom type="plane" size="0 0 0.03" material="matplane" rgba="1 1 1 1" />
        <camera name="body_cam" mode="fixed" pos="20 0.1 0.05" euler="90 90 0" fovy="1" />
        <camera name="top camera" mode="fixed" pos="0 -1 30" euler="0 0 180" fovy="6" />

        <body name="mouse" pos="0 0.036 0.113" euler="0 0 0">

            <site name="body_ss" pos="0 0 0" size="0.002" rgba=".9 .9 0 1" />

            <joint name="slider_x" type="slide" pos="0 0 0" axis="1 0 0" damping="0.2" />
            <joint name="slider_y" type="slide" pos="0 0 0" axis="0 1 0" damping="0.2" />
            <joint name="hinge_z" type="hinge" pos="0 0 0" axis="0 0 1" damping="0.1" />


            <geom name="visual_mouse_bracket" type="mesh" mesh="head_mounting" rgba="0.95 0.95 0.95 1" />

            <body name="mouse_head" pos="0 -0.0106 0.0144" euler="0 0 0">

                <geom name="visual_mouse_head" type="mesh" mesh="head" mass="2" friction="1" rgba="0.95 0.95 0.95 1" />
                <camera name="head camera" mode="fixed" pos="0 -0.04 0" euler="90 180 0" />

                <body name="whisker left front 1" pos="0.0 -0.05 -0.01" euler="0 0 45">

                    <joint name="whisker left front 11" pos="0 -0.0 -0" type="hinge" axis="-1 -1 0" stiffness="0.001" armature="0.00065" damping="0.0007" ref="0" />
                    <joint name="whisker left front 12" pos="0 -0.0 -0" type="hinge" axis="0 0 1" stiffness="0.001" armature="0.00065" damping="0.0007" ref="0" />
                    <geom name="whisk_left front 1" type="capsule" fromto="0 -0.0 -0 0 -0.005 -0" size="0.001" rgba="0.5 0.5 0.5 1" mass="0.0001" />
                    <body name="whisker left front 2" pos="0 0 0" euler="0 0 0">
                        <joint name="whisker left front 21" pos="0 -0.005 -0" type="hinge" axis="-1 -1 0" stiffness="0.001" armature="0.00065" damping="0.0007" ref="0" />
                        <joint name="whisker left front 22" pos="0 -0.005 -0" type="hinge" axis="0 0 1" stiffness="0.001" armature="0.00065" damping="0.0007" ref="0" />
                        <geom name="whisk_left front 2" type="capsule" fromto="0 -0.005 -0 0 -0.01 -0" size="0.001" rgba="0.5 0.5 0.5 1" mass="0.0001" />
                        <body name="whisker left front 3" pos="0 0 0" euler="0 0 0">
                            <joint name="whisker left front 31" pos="0 -0.01 -0" type="hinge" axis="-1 -1 0" stiffness="0.001" armature="0.00065" damping="0.0007" ref="0" />
                            <joint name="whisker left front 32" pos="0 -0.01 -0" type="hinge" axis="0 0 1" stiffness="0.001" armature="0.00065" damping="0.0007" ref="0" />
                            <geom name="whisk_left front 3" type="capsule" fromto="0 -0.01 -0 0 -0.015 -0" size="0.001" rgba="0.5 0.5 0.5 1" mass="0.0001" />
                            <body name="whisker left front 4" pos="0 0 0" euler="0 0 0">
                                <joint name="whisker left front 41" pos="0 -0.015 -0" type="hinge" axis="-1 -1 0" stiffness="0.001" armature="0.00065" damping="0.0007" ref="0" />
                                <joint name="whisker left front 42" pos="0 -0.015 -0" type="hinge" axis="0 0 1" stiffness="0.001" armature="0.00065" damping="0.0007" ref="0" />
                                <geom name="whisk_left front 4" type="capsule" fromto="0 -0.015 -0 0 -0.02 -0" size="0.001" rgba="0.5 0.5 0.5 1" mass="0.0001" />

                            </body>
                        </body>
                    </body>
                </body>
                <body name="whisker left hind 1" pos="0.009000000000000001 -0.04 -0.01" euler="0 0 55">

                    <joint name="whisker left hind 11" pos="0 -0.0 -0" type="hinge" axis="-1 -1 0" stiffness="0.001" armature="0.00065" damping="0.0007" ref="0" />
                    <joint name="whisker left hind 12" pos="0 -0.0 -0" type="hinge" axis="0 0 1" stiffness="0.001" armature="0.00065" damping="0.0007" ref="0" />
                    <geom name="whisk_left hind 1" type="capsule" fromto="0 -0.0 -0 0 -0.005 -0" size="0.001" rgba="0.5 0.5 0.5 1" mass="0.0001" />
                    <body name="whisker left hind 2" pos="0 0 0" euler="0 0 0">
                        <joint name="whisker left hind 21" pos="0 -0.005 -0" type="hinge" axis="-1 -1 0" stiffness="0.001" armature="0.00065" damping="0.0007" ref="0" />
                        <joint name="whisker left hind 22" pos="0 -0.005 -0" type="hinge" axis="0 0 1" stiffness="0.001" armature="0.00065" damping="0.0007" ref="0" />
                        <geom name="whisk_left hind 2" type="capsule" fromto="0 -0.005 -0 0 -0.01 -0" size="0.001" rgba="0.5 0.5 0.5 1" mass="0.0001" />
                        <body name="whisker left hind 3" pos="0 0 0" euler="0 0 0">
                            <joint name="whisker left hind 31" pos="0 -0.01 -0" type="hinge" axis="-1 -1 0" stiffness="0.001" armature="0.00065" damping="0.0007" ref="0" />
                            <joint name="whisker left hind 32" pos="0 -0.01 -0" type="hinge" axis="0 0 1" stiffness="0.001" armature="0.00065" damping="0.0007" ref="0" />
                            <geom name="whisk_left hind 3" type="capsule" fromto="0 -0.01 -0 0 -0.015 -0" size="0.001" rgba="0.5 0.5 0.5 1" mass="0.0001" />
                            <body name="whisker left hind 4" pos="0 0 0" euler="0 0 0">
                                <joint name="whisker left hind 41" pos="0 -0.015 -0" type="hinge" axis="-1 -1 0" stiffness="0.001" armature="0.00065" damping="0.0007" ref="0" />
                                <joint name="whisker left hind 42" pos="0 -0.015 -0" type="hinge" axis="0 0 1" stiffness="0.001" armature="0.00065" damping="0.0007" ref="0" />
                                <geom name="whisk_left hind 4" type="capsule" fromto="0 -0.015 -0 0 -0.02 -0" size="0.001" rgba="0.5 0.5 0.5 1" mass="0.0001" />
                                <body name="whisker left hind 5" pos="0 0 0" euler="0 0 0">
                                    <joint name="whisker left hind 51" pos="0 -0.02 -0" type="hinge" axis="-1 -1 0" stiffness="0.001" armature="0.00065" damping="0.0007" ref="0" />
                                    <joint name="whisker left hind 52" pos="0 -0.02 -0" type="hinge" axis="0 0 1" stiffness="0.001" armature="0.00065" damping="0.0007" ref="0" />
                                    <geom name="whisk_left hind 5" type="capsule" fromto="0 -0.02 -0 0 -0.025 -0" size="0.001" rgba="0.5 0.5 0.5 1" mass="0.0001" />

                                </body>
                            </body>
                        </body>
                    </body>
                </body>

                <body name="whisker right front 1" pos="0.001 -0.05 -0.01" euler="0 0 -45">

                    <joint name="whisker right front 11" pos="0 -0.0 -0" type="hinge" axis="-1 -1 0" stiffness="0.001" armature="0.00065" damping="0.0007" ref="0" />
                    <joint name="whisker right front 12" pos="0 -0.0 -0" type="hinge" axis="0 0 1" stiffness="0.001" armature="0.00065" damping="0.0007" ref="0" />
                    <geom name="whisk_right front 1" type="capsule" fromto="0 -0.0 -0 0 -0.005 -0" size="0.001" rgba="0.5 0.5 0.5 1" mass="0.0001" />
                    <body name="whisker right front 2" pos="0 0 0" euler="0 0 0">
                        <joint name="whisker right front 21" pos="0 -0.005 -0" type="hinge" axis="-1 -1 0" stiffness="0.001" armature="0.00065" damping="0.0007" ref="0" />
                        <joint name="whisker right front 22" pos="0 -0.005 -0" type="hinge" axis="0 0 1" stiffness="0.001" armature="0.00065" damping="0.0007" ref="0" />
                        <geom name="whisk_right front 2" type="capsule" fromto="0 -0.005 -0 0 -0.01 -0" size="0.001" rgba="0.5 0.5 0.5 1" mass="0.0001" />
                        <body name="whisker right front 3" pos="0 0 0" euler="0 0 0">
                            <joint name="whisker right front 31" pos="0 -0.01 -0" type="hinge" axis="-1 -1 0" stiffness="0.001" armature="0.00065" damping="0.0007" ref="0" />
                            <joint name="whisker right front 32" pos="0 -0.01 -0" type="hinge" axis="0 0 1" stiffness="0.001" armature="0.00065" damping="0.0007" ref="0" />
                            <geom name="whisk_right front 3" type="capsule" fromto="0 -0.01 -0 0 -0.015 -0" size="0.001" rgba="0.5 0.5 0.5 1" mass="0.0001" />
                            <body name="whisker right front 4" pos="0 0 0" euler="0 0 0">
                                <joint name="whisker right front 41" pos="0 -0.015 -0" type="hinge" axis="-1 -1 0" stiffness="0.001" armature="0.00065" damping="0.0007" ref="0" />
                                <joint name="whisker right front 42" pos="0 -0.015 -0" type="hinge" axis="0 0 1" stiffness="0.001" armature="0.00065" damping="0.0007" ref="0" />
                                <geom name="whisk_right front 4" type="capsule" fromto="0 -0.015 -0 0 -0.02 -0" size="0.001" rgba="0.5 0.5 0.5 1" mass="0.0001" />

                            </body>
                        </body>
                    </body>
                </body>

                <body name="whisker right hind 1" pos="-0.007 -0.04 -0.01" euler="0 0 -55">

                    <joint name="whisker right hind 11" pos="0 -0.0 -0" type="hinge" axis="-1 -1 0" stiffness="0.001" armature="0.00065" damping="0.0007" ref="0" />
                    <joint name="whisker right hind 12" pos="0 -0.0 -0" type="hinge" axis="0 0 1" stiffness="0.001" armature="0.00065" damping="0.0007" ref="0" />
                    <geom name="whisk_right hind 1" type="capsule" fromto="0 -0.0 -0 0 -0.005 -0" size="0.001" rgba="0.5 0.5 0.5 1" mass="0.0001" />
                    <body name="whisker right hind 2" pos="0 0 0" euler="0 0 0">
                        <joint name="whisker right hind 21" pos="0 -0.005 -0" type="hinge" axis="-1 -1 0" stiffness="0.001" armature="0.00065" damping="0.0007" ref="0" />
                        <joint name="whisker right hind 22" pos="0 -0.005 -0" type="hinge" axis="0 0 1" stiffness="0.001" armature="0.00065" damping="0.0007" ref="0" />
                        <geom name="whisk_right hind 2" type="capsule" fromto="0 -0.005 -0 0 -0.01 -0" size="0.001" rgba="0.5 0.5 0.5 1" mass="0.0001" />
                        <body name="whisker right hind 3" pos="0 0 0" euler="0 0 0">
                            <joint name="whisker right hind 31" pos="0 -0.01 -0" type="hinge" axis="-1 -1 0" stiffness="0.001" armature="0.00065" damping="0.0007" ref="0" />
                            <joint name="whisker right hind 32" pos="0 -0.01 -0" type="hinge" axis="0 0 1" stiffness="0.001" armature="0.00065" damping="0.0007" ref="0" />
                            <geom name="whisk_right hind 3" type="capsule" fromto="0 -0.01 -0 0 -0.015 -0" size="0.001" rgba="0.5 0.5 0.5 1" mass="0.0001" />
                            <body name="whisker right hind 4" pos="0 0 0" euler="0 0 0">
                                <joint name="whisker right hind 41" pos="0 -0.015 -0" type="hinge" axis="-1 -1 0" stiffness="0.001" armature="0.00065" damping="0.0007" ref="0" />
                                <joint name="whisker right hind 42" pos="0 -0.015 -0" type="hinge" axis="0 0 1" stiffness="0.001" armature="0.00065" damping="0.0007" ref="0" />
                                <geom name="whisk_right hind 4" type="capsule" fromto="0 -0.015 -0 0 -0.02 -0" size="0.001" rgba="0.5 0.5 0.5 1" mass="0.0001" />
                                <body name="whisker right hind 5" pos="0 0 0" euler="0 0 0">
                                    <joint name="whisker right hind 51" pos="0 -0.02 -0" type="hinge" axis="-1 -1 0" stiffness="0.001" armature="0.00065" damping="0.0007" ref="0" />
                                    <joint name="whisker right hind 52" pos="0 -0.02 -0" type="hinge" axis="0 0 1" stiffness="0.001" armature="0.00065" damping="0.0007" ref="0" />
                                    <geom name="whisk_right hind 5" type="capsule" fromto="0 -0.02 -0 0 -0.025 -0" size="0.001" rgba="0.5 0.5 0.5 1" mass="0.0001" />

                                </body>
                            </body>
                        </body>
                    </body>
                </body>


            </body>
        </body>

        <include file="test_environment/maze1.xml" />

    </worldbody>



</mujoco>